Downloading: "https://github.com/mseitzer/pytorch-fid/releases/download/fid_weights/pt_inception-2015-12-05-6726825d.pth" to /home_data/home/v-lijm/.cache/torch/hub/checkpoints/pt_inception-2015-12-05-6726825d.pth
Traceback (most recent call last):
  File "/home_data/home/v-lijm/anaconda3/envs/react/lib/python3.8/urllib/request.py", line 1354, in do_open
    h.request(req.get_method(), req.selector, req.data, headers,
  File "/home_data/home/v-lijm/anaconda3/envs/react/lib/python3.8/http/client.py", line 1256, in request
    self._send_request(method, url, body, headers, encode_chunked)
  File "/home_data/home/v-lijm/anaconda3/envs/react/lib/python3.8/http/client.py", line 1302, in _send_request
    self.endheaders(body, encode_chunked=encode_chunked)
  File "/home_data/home/v-lijm/anaconda3/envs/react/lib/python3.8/http/client.py", line 1251, in endheaders
    self._send_output(message_body, encode_chunked=encode_chunked)
  File "/home_data/home/v-lijm/anaconda3/envs/react/lib/python3.8/http/client.py", line 1011, in _send_output
    self.send(msg)
  File "/home_data/home/v-lijm/anaconda3/envs/react/lib/python3.8/http/client.py", line 951, in send
    self.connect()
  File "/home_data/home/v-lijm/anaconda3/envs/react/lib/python3.8/http/client.py", line 1418, in connect
    super().connect()
  File "/home_data/home/v-lijm/anaconda3/envs/react/lib/python3.8/http/client.py", line 922, in connect
    self.sock = self._create_connection(
  File "/home_data/home/v-lijm/anaconda3/envs/react/lib/python3.8/socket.py", line 787, in create_connection
    for res in getaddrinfo(host, port, 0, SOCK_STREAM):
  File "/home_data/home/v-lijm/anaconda3/envs/react/lib/python3.8/socket.py", line 918, in getaddrinfo
    for res in _socket.getaddrinfo(host, port, family, type, proto, flags):
socket.gaierror: [Errno -2] Name or service not known

During handling of the above exception, another exception occurred:

Traceback (most recent call last):
  File "/home_data/home/v-lijm/anaconda3/envs/react/lib/python3.8/runpy.py", line 194, in _run_module_as_main
    return _run_code(code, main_globals, None,
  File "/home_data/home/v-lijm/anaconda3/envs/react/lib/python3.8/runpy.py", line 87, in _run_code
    exec(code, run_globals)
  File "/home_data/home/v-lijm/anaconda3/envs/react/lib/python3.8/site-packages/pytorch_fid/__main__.py", line 3, in <module>
    pytorch_fid.fid_score.main()
  File "/home_data/home/v-lijm/anaconda3/envs/react/lib/python3.8/site-packages/pytorch_fid/fid_score.py", line 313, in main
    fid_value = calculate_fid_given_paths(args.path,
  File "/home_data/home/v-lijm/anaconda3/envs/react/lib/python3.8/site-packages/pytorch_fid/fid_score.py", line 257, in calculate_fid_given_paths
    model = InceptionV3([block_idx]).to(device)
  File "/home_data/home/v-lijm/anaconda3/envs/react/lib/python3.8/site-packages/pytorch_fid/inception.py", line 80, in __init__
    inception = fid_inception_v3()
  File "/home_data/home/v-lijm/anaconda3/envs/react/lib/python3.8/site-packages/pytorch_fid/inception.py", line 219, in fid_inception_v3
    state_dict = load_state_dict_from_url(FID_WEIGHTS_URL, progress=True)
  File "/home_data/home/v-lijm/anaconda3/envs/react/lib/python3.8/site-packages/torch/hub.py", line 571, in load_state_dict_from_url
    download_url_to_file(url, cached_file, hash_prefix, progress=progress)
  File "/home_data/home/v-lijm/anaconda3/envs/react/lib/python3.8/site-packages/torch/hub.py", line 437, in download_url_to_file
    u = urlopen(req)
  File "/home_data/home/v-lijm/anaconda3/envs/react/lib/python3.8/urllib/request.py", line 222, in urlopen
    return opener.open(url, data, timeout)
  File "/home_data/home/v-lijm/anaconda3/envs/react/lib/python3.8/urllib/request.py", line 525, in open
    response = self._open(req, data)
  File "/home_data/home/v-lijm/anaconda3/envs/react/lib/python3.8/urllib/request.py", line 542, in _open
    result = self._call_chain(self.handle_open, protocol, protocol +
  File "/home_data/home/v-lijm/anaconda3/envs/react/lib/python3.8/urllib/request.py", line 502, in _call_chain
    result = func(*args)
  File "/home_data/home/v-lijm/anaconda3/envs/react/lib/python3.8/urllib/request.py", line 1397, in https_open
    return self.do_open(http.client.HTTPSConnection, req,
  File "/home_data/home/v-lijm/anaconda3/envs/react/lib/python3.8/urllib/request.py", line 1357, in do_open
    raise URLError(err)
urllib.error.URLError: <urlopen error [Errno -2] Name or service not known>
